2023-12-31 11:17:40,775 INFO    StreamThr :82612 [internal.py:wandb_internal():87] W&B internal server running at pid: 82612, started at: 2023-12-31 11:17:40.774654
2023-12-31 11:17:40,775 DEBUG   HandlerThread:82612 [handler.py:handle_request():144] handle_request: status
2023-12-31 11:17:40,778 INFO    WriterThread:82612 [datastore.py:open_for_write():85] open: /Users/sigurdrollsolberg/Documents/School/MasterPublication/DDPN/wandb/run-20231231_111740-o51by6bi/run-o51by6bi.wandb
2023-12-31 11:17:40,779 DEBUG   SenderThread:82612 [sender.py:send():336] send: header
2023-12-31 11:17:40,824 DEBUG   SenderThread:82612 [sender.py:send():336] send: run
2023-12-31 11:17:44,128 INFO    SenderThread:82612 [retry.py:__call__():172] Retry attempt failed:
Traceback (most recent call last):
  File "/Users/sigurdrollsolberg/opt/anaconda3/envs/aml_2/lib/python3.9/site-packages/urllib3/connection.py", line 174, in _new_conn
    conn = connection.create_connection(
  File "/Users/sigurdrollsolberg/opt/anaconda3/envs/aml_2/lib/python3.9/site-packages/urllib3/util/connection.py", line 72, in create_connection
    for res in socket.getaddrinfo(host, port, family, socket.SOCK_STREAM):
  File "/Users/sigurdrollsolberg/opt/anaconda3/envs/aml_2/lib/python3.9/socket.py", line 954, in getaddrinfo
    for res in _socket.getaddrinfo(host, port, family, type, proto, flags):
socket.gaierror: [Errno 8] nodename nor servname provided, or not known

During handling of the above exception, another exception occurred:

Traceback (most recent call last):
  File "/Users/sigurdrollsolberg/opt/anaconda3/envs/aml_2/lib/python3.9/site-packages/urllib3/connectionpool.py", line 703, in urlopen
    httplib_response = self._make_request(
  File "/Users/sigurdrollsolberg/opt/anaconda3/envs/aml_2/lib/python3.9/site-packages/urllib3/connectionpool.py", line 386, in _make_request
    self._validate_conn(conn)
  File "/Users/sigurdrollsolberg/opt/anaconda3/envs/aml_2/lib/python3.9/site-packages/urllib3/connectionpool.py", line 1042, in _validate_conn
    conn.connect()
  File "/Users/sigurdrollsolberg/opt/anaconda3/envs/aml_2/lib/python3.9/site-packages/urllib3/connection.py", line 358, in connect
    self.sock = conn = self._new_conn()
  File "/Users/sigurdrollsolberg/opt/anaconda3/envs/aml_2/lib/python3.9/site-packages/urllib3/connection.py", line 186, in _new_conn
    raise NewConnectionError(
urllib3.exceptions.NewConnectionError: <urllib3.connection.HTTPSConnection object at 0x7f91a8022430>: Failed to establish a new connection: [Errno 8] nodename nor servname provided, or not known

During handling of the above exception, another exception occurred:

Traceback (most recent call last):
  File "/Users/sigurdrollsolberg/opt/anaconda3/envs/aml_2/lib/python3.9/site-packages/requests/adapters.py", line 486, in send
    resp = conn.urlopen(
  File "/Users/sigurdrollsolberg/opt/anaconda3/envs/aml_2/lib/python3.9/site-packages/urllib3/connectionpool.py", line 787, in urlopen
    retries = retries.increment(
  File "/Users/sigurdrollsolberg/opt/anaconda3/envs/aml_2/lib/python3.9/site-packages/urllib3/util/retry.py", line 592, in increment
    raise MaxRetryError(_pool, url, error or ResponseError(cause))
urllib3.exceptions.MaxRetryError: HTTPSConnectionPool(host='api.wandb.ai', port=443): Max retries exceeded with url: /graphql (Caused by NewConnectionError('<urllib3.connection.HTTPSConnection object at 0x7f91a8022430>: Failed to establish a new connection: [Errno 8] nodename nor servname provided, or not known'))

During handling of the above exception, another exception occurred:

Traceback (most recent call last):
  File "/Users/sigurdrollsolberg/opt/anaconda3/envs/aml_2/lib/python3.9/site-packages/wandb/sdk/lib/retry.py", line 131, in __call__
    result = self._call_fn(*args, **kwargs)
  File "/Users/sigurdrollsolberg/opt/anaconda3/envs/aml_2/lib/python3.9/site-packages/wandb/sdk/internal/internal_api.py", line 242, in execute
    return self.client.execute(*args, **kwargs)  # type: ignore
  File "/Users/sigurdrollsolberg/opt/anaconda3/envs/aml_2/lib/python3.9/site-packages/wandb/vendor/gql-0.2.0/wandb_gql/client.py", line 52, in execute
    result = self._get_result(document, *args, **kwargs)
  File "/Users/sigurdrollsolberg/opt/anaconda3/envs/aml_2/lib/python3.9/site-packages/wandb/vendor/gql-0.2.0/wandb_gql/client.py", line 60, in _get_result
    return self.transport.execute(document, *args, **kwargs)
  File "/Users/sigurdrollsolberg/opt/anaconda3/envs/aml_2/lib/python3.9/site-packages/wandb/vendor/gql-0.2.0/wandb_gql/transport/requests.py", line 38, in execute
    request = requests.post(self.url, **post_args)
  File "/Users/sigurdrollsolberg/opt/anaconda3/envs/aml_2/lib/python3.9/site-packages/requests/api.py", line 115, in post
    return request("post", url, data=data, json=json, **kwargs)
  File "/Users/sigurdrollsolberg/opt/anaconda3/envs/aml_2/lib/python3.9/site-packages/requests/api.py", line 59, in request
    return session.request(method=method, url=url, **kwargs)
  File "/Users/sigurdrollsolberg/opt/anaconda3/envs/aml_2/lib/python3.9/site-packages/requests/sessions.py", line 589, in request
    resp = self.send(prep, **send_kwargs)
  File "/Users/sigurdrollsolberg/opt/anaconda3/envs/aml_2/lib/python3.9/site-packages/requests/sessions.py", line 703, in send
    r = adapter.send(request, **kwargs)
  File "/Users/sigurdrollsolberg/opt/anaconda3/envs/aml_2/lib/python3.9/site-packages/requests/adapters.py", line 519, in send
    raise ConnectionError(e, request=request)
requests.exceptions.ConnectionError: HTTPSConnectionPool(host='api.wandb.ai', port=443): Max retries exceeded with url: /graphql (Caused by NewConnectionError('<urllib3.connection.HTTPSConnection object at 0x7f91a8022430>: Failed to establish a new connection: [Errno 8] nodename nor servname provided, or not known'))
2023-12-31 11:17:45,848 DEBUG   HandlerThread:82612 [handler.py:handle_request():144] handle_request: keepalive
2023-12-31 11:17:50,869 DEBUG   HandlerThread:82612 [handler.py:handle_request():144] handle_request: keepalive
2023-12-31 11:17:55,890 DEBUG   HandlerThread:82612 [handler.py:handle_request():144] handle_request: keepalive
2023-12-31 11:18:00,914 DEBUG   HandlerThread:82612 [handler.py:handle_request():144] handle_request: keepalive
2023-12-31 11:18:05,938 DEBUG   HandlerThread:82612 [handler.py:handle_request():144] handle_request: keepalive
2023-12-31 11:18:10,961 DEBUG   HandlerThread:82612 [handler.py:handle_request():144] handle_request: keepalive
2023-12-31 11:18:15,982 DEBUG   HandlerThread:82612 [handler.py:handle_request():144] handle_request: keepalive
2023-12-31 11:18:21,000 DEBUG   HandlerThread:82612 [handler.py:handle_request():144] handle_request: keepalive
2023-12-31 11:18:26,022 DEBUG   HandlerThread:82612 [handler.py:handle_request():144] handle_request: keepalive
2023-12-31 11:18:31,048 DEBUG   HandlerThread:82612 [handler.py:handle_request():144] handle_request: keepalive
2023-12-31 11:18:36,066 DEBUG   HandlerThread:82612 [handler.py:handle_request():144] handle_request: keepalive
2023-12-31 11:18:41,086 DEBUG   HandlerThread:82612 [handler.py:handle_request():144] handle_request: cancel
2023-12-31 11:18:41,086 DEBUG   HandlerThread:82612 [handler.py:handle_request():144] handle_request: cancel
2023-12-31 11:18:41,086 DEBUG   SenderThread:82612 [sender.py:send():345] Record cancelled: run
2023-12-31 11:18:41,086 DEBUG   HandlerThread:82612 [handler.py:handle_request():144] handle_request: status_report
2023-12-31 11:18:43,126 DEBUG   HandlerThread:82612 [handler.py:handle_request():144] handle_request: shutdown
2023-12-31 11:18:43,127 INFO    HandlerThread:82612 [handler.py:finish():841] shutting down handler
2023-12-31 11:18:44,096 INFO    WriterThread:82612 [datastore.py:close():299] close: /Users/sigurdrollsolberg/Documents/School/MasterPublication/DDPN/wandb/run-20231231_111740-o51by6bi/run-o51by6bi.wandb
2023-12-31 11:18:44,096 INFO    SenderThread:82612 [sender.py:finish():1493] shutting down sender
