2023-12-31 10:51:11,016 INFO    StreamThr :79067 [internal.py:wandb_internal():87] W&B internal server running at pid: 79067, started at: 2023-12-31 10:51:11.016137
2023-12-31 10:51:11,017 DEBUG   HandlerThread:79067 [handler.py:handle_request():144] handle_request: status
2023-12-31 10:51:11,020 INFO    WriterThread:79067 [datastore.py:open_for_write():85] open: /Users/sigurdrollsolberg/Documents/School/MasterPublication/DDPN/wandb/run-20231231_105111-rs7ful98/run-rs7ful98.wandb
2023-12-31 10:51:11,020 DEBUG   SenderThread:79067 [sender.py:send():336] send: header
2023-12-31 10:51:11,066 DEBUG   SenderThread:79067 [sender.py:send():336] send: run
2023-12-31 10:51:16,092 DEBUG   HandlerThread:79067 [handler.py:handle_request():144] handle_request: keepalive
2023-12-31 10:51:21,110 DEBUG   HandlerThread:79067 [handler.py:handle_request():144] handle_request: keepalive
2023-12-31 10:51:26,133 DEBUG   HandlerThread:79067 [handler.py:handle_request():144] handle_request: keepalive
2023-12-31 10:51:31,153 DEBUG   HandlerThread:79067 [handler.py:handle_request():144] handle_request: keepalive
2023-12-31 10:51:36,175 DEBUG   HandlerThread:79067 [handler.py:handle_request():144] handle_request: keepalive
2023-12-31 10:51:41,187 DEBUG   HandlerThread:79067 [handler.py:handle_request():144] handle_request: keepalive
2023-12-31 10:51:44,495 INFO    SenderThread:79067 [retry.py:__call__():172] Retry attempt failed:
Traceback (most recent call last):
  File "/Users/sigurdrollsolberg/opt/anaconda3/envs/aml_2/lib/python3.9/site-packages/urllib3/connection.py", line 174, in _new_conn
    conn = connection.create_connection(
  File "/Users/sigurdrollsolberg/opt/anaconda3/envs/aml_2/lib/python3.9/site-packages/urllib3/util/connection.py", line 95, in create_connection
    raise err
  File "/Users/sigurdrollsolberg/opt/anaconda3/envs/aml_2/lib/python3.9/site-packages/urllib3/util/connection.py", line 85, in create_connection
    sock.connect(sa)
socket.timeout: timed out

During handling of the above exception, another exception occurred:

Traceback (most recent call last):
  File "/Users/sigurdrollsolberg/opt/anaconda3/envs/aml_2/lib/python3.9/site-packages/urllib3/connectionpool.py", line 703, in urlopen
    httplib_response = self._make_request(
  File "/Users/sigurdrollsolberg/opt/anaconda3/envs/aml_2/lib/python3.9/site-packages/urllib3/connectionpool.py", line 386, in _make_request
    self._validate_conn(conn)
  File "/Users/sigurdrollsolberg/opt/anaconda3/envs/aml_2/lib/python3.9/site-packages/urllib3/connectionpool.py", line 1042, in _validate_conn
    conn.connect()
  File "/Users/sigurdrollsolberg/opt/anaconda3/envs/aml_2/lib/python3.9/site-packages/urllib3/connection.py", line 358, in connect
    self.sock = conn = self._new_conn()
  File "/Users/sigurdrollsolberg/opt/anaconda3/envs/aml_2/lib/python3.9/site-packages/urllib3/connection.py", line 179, in _new_conn
    raise ConnectTimeoutError(
urllib3.exceptions.ConnectTimeoutError: (<urllib3.connection.HTTPSConnection object at 0x7f9890af9850>, 'Connection to api.wandb.ai timed out. (connect timeout=10)')

During handling of the above exception, another exception occurred:

Traceback (most recent call last):
  File "/Users/sigurdrollsolberg/opt/anaconda3/envs/aml_2/lib/python3.9/site-packages/requests/adapters.py", line 486, in send
    resp = conn.urlopen(
  File "/Users/sigurdrollsolberg/opt/anaconda3/envs/aml_2/lib/python3.9/site-packages/urllib3/connectionpool.py", line 787, in urlopen
    retries = retries.increment(
  File "/Users/sigurdrollsolberg/opt/anaconda3/envs/aml_2/lib/python3.9/site-packages/urllib3/util/retry.py", line 592, in increment
    raise MaxRetryError(_pool, url, error or ResponseError(cause))
urllib3.exceptions.MaxRetryError: HTTPSConnectionPool(host='api.wandb.ai', port=443): Max retries exceeded with url: /graphql (Caused by ConnectTimeoutError(<urllib3.connection.HTTPSConnection object at 0x7f9890af9850>, 'Connection to api.wandb.ai timed out. (connect timeout=10)'))

During handling of the above exception, another exception occurred:

Traceback (most recent call last):
  File "/Users/sigurdrollsolberg/opt/anaconda3/envs/aml_2/lib/python3.9/site-packages/wandb/sdk/lib/retry.py", line 131, in __call__
    result = self._call_fn(*args, **kwargs)
  File "/Users/sigurdrollsolberg/opt/anaconda3/envs/aml_2/lib/python3.9/site-packages/wandb/sdk/internal/internal_api.py", line 242, in execute
    return self.client.execute(*args, **kwargs)  # type: ignore
  File "/Users/sigurdrollsolberg/opt/anaconda3/envs/aml_2/lib/python3.9/site-packages/wandb/vendor/gql-0.2.0/wandb_gql/client.py", line 52, in execute
    result = self._get_result(document, *args, **kwargs)
  File "/Users/sigurdrollsolberg/opt/anaconda3/envs/aml_2/lib/python3.9/site-packages/wandb/vendor/gql-0.2.0/wandb_gql/client.py", line 60, in _get_result
    return self.transport.execute(document, *args, **kwargs)
  File "/Users/sigurdrollsolberg/opt/anaconda3/envs/aml_2/lib/python3.9/site-packages/wandb/vendor/gql-0.2.0/wandb_gql/transport/requests.py", line 38, in execute
    request = requests.post(self.url, **post_args)
  File "/Users/sigurdrollsolberg/opt/anaconda3/envs/aml_2/lib/python3.9/site-packages/requests/api.py", line 115, in post
    return request("post", url, data=data, json=json, **kwargs)
  File "/Users/sigurdrollsolberg/opt/anaconda3/envs/aml_2/lib/python3.9/site-packages/requests/api.py", line 59, in request
    return session.request(method=method, url=url, **kwargs)
  File "/Users/sigurdrollsolberg/opt/anaconda3/envs/aml_2/lib/python3.9/site-packages/requests/sessions.py", line 589, in request
    resp = self.send(prep, **send_kwargs)
  File "/Users/sigurdrollsolberg/opt/anaconda3/envs/aml_2/lib/python3.9/site-packages/requests/sessions.py", line 703, in send
    r = adapter.send(request, **kwargs)
  File "/Users/sigurdrollsolberg/opt/anaconda3/envs/aml_2/lib/python3.9/site-packages/requests/adapters.py", line 507, in send
    raise ConnectTimeout(e, request=request)
requests.exceptions.ConnectTimeout: HTTPSConnectionPool(host='api.wandb.ai', port=443): Max retries exceeded with url: /graphql (Caused by ConnectTimeoutError(<urllib3.connection.HTTPSConnection object at 0x7f9890af9850>, 'Connection to api.wandb.ai timed out. (connect timeout=10)'))
2023-12-31 10:51:46,206 DEBUG   HandlerThread:79067 [handler.py:handle_request():144] handle_request: keepalive
2023-12-31 10:51:51,226 DEBUG   HandlerThread:79067 [handler.py:handle_request():144] handle_request: keepalive
2023-12-31 10:51:56,249 DEBUG   HandlerThread:79067 [handler.py:handle_request():144] handle_request: keepalive
2023-12-31 10:52:01,273 DEBUG   HandlerThread:79067 [handler.py:handle_request():144] handle_request: keepalive
2023-12-31 10:52:06,295 DEBUG   HandlerThread:79067 [handler.py:handle_request():144] handle_request: keepalive
2023-12-31 10:52:11,316 DEBUG   HandlerThread:79067 [handler.py:handle_request():144] handle_request: cancel
2023-12-31 10:52:11,319 DEBUG   HandlerThread:79067 [handler.py:handle_request():144] handle_request: cancel
2023-12-31 10:52:11,320 DEBUG   SenderThread:79067 [sender.py:send():345] Record cancelled: run
2023-12-31 10:52:11,321 DEBUG   HandlerThread:79067 [handler.py:handle_request():144] handle_request: status_report
2023-12-31 10:52:13,373 DEBUG   HandlerThread:79067 [handler.py:handle_request():144] handle_request: shutdown
2023-12-31 10:52:13,374 INFO    HandlerThread:79067 [handler.py:finish():841] shutting down handler
2023-12-31 10:52:14,332 INFO    SenderThread:79067 [sender.py:finish():1493] shutting down sender
2023-12-31 10:52:14,333 INFO    WriterThread:79067 [datastore.py:close():299] close: /Users/sigurdrollsolberg/Documents/School/MasterPublication/DDPN/wandb/run-20231231_105111-rs7ful98/run-rs7ful98.wandb
